<?xml version='1.0' encoding='utf-8'?>
<mujoco model="ur5_robot">
  <compiler angle="radian" />
  <asset>
    <mesh name="base" file="base.stl" />
    <mesh name="shoulder" file="shoulder.stl" />
    <mesh name="upperarm" file="upperarm.stl" />
    <mesh name="forearm" file="forearm.stl" />
    <mesh name="wrist1" file="wrist1.stl" />
    <mesh name="wrist2" file="wrist2.stl" />
    <mesh name="wrist3" file="wrist3.stl" />
  </asset>
  <worldbody>
    <geom quat="-1 0 0 0" type="mesh" rgba="0.7 0.7 0.7 1" mesh="base" />
    <body name="shoulder_link" pos="0 0 0.089159" quat="0 0 0 1">
      <inertial pos="0 -0.00193 -0.02561" mass="3.7" diaginertia="0.0149724 0.0149724 0.0104063" />
      <joint name="shoulder_pan_joint" pos="0 0 0" axis="0 0 1" range="-6.28319 6.28319" actuatorfrcrange="-150 150" />
      <geom quat="0 0 0 1" type="mesh" rgba="0.7 0.7 0.7 1" mesh="shoulder" />
      <body name="upper_arm_link" quat="0.707107 0.707107 0 0">
        <inertial pos="-0.2125 0 0.11336" mass="8.393" diaginertia="0.133886 0.133886 0.0151074" />
        <joint name="shoulder_lift_joint" pos="0 0 0" axis="0 0 1" range="-6.28319 6.28319" actuatorfrcrange="-150 150" />
        <geom pos="0 0 0.13585" quat="0.5 0.5 -0.5 -0.5" type="mesh" rgba="0.7 0.7 0.7 1" mesh="upperarm" />
        <body name="forearm_link" pos="-0.425 0 0">
          <inertial pos="-0.24225 0 0.0265" mass="2.33" diaginertia="0.0312168 0.0312168 0.004095" />
          <joint name="elbow_joint" pos="0 0 0" axis="0 0 1" range="-3.14159 3.14159" actuatorfrcrange="-150 150" />
          <geom pos="0 0 0.0165" quat="0.5 0.5 -0.5 -0.5" type="mesh" rgba="0.7 0.7 0.7 1" mesh="forearm" />
          <body name="wrist_1_link" pos="-0.39225 0 0.10915">
            <inertial pos="0 -0.01634 -0.0018" quat="0.5 0.5 -0.5 0.5" mass="1.219" diaginertia="0.0021942 0.00201389 0.00201389" />
            <joint name="wrist_1_joint" pos="0 0 0" axis="0 0 1" range="-6.28319 6.28319" actuatorfrcrange="-28 28" />
            <geom pos="0 0 -0.093" quat="0.707107 0.707107 0 0" type="mesh" rgba="0.7 0.7 0.7 1" mesh="wrist1" />
            <body name="wrist_2_link" pos="0 -0.09465 -1.9413e-11" quat="0.707107 0.707107 0 0">
              <inertial pos="0 0.01634 -0.0018" quat="0.5 0.5 -0.5 0.5" mass="1.219" diaginertia="0.0021942 0.00183104 0.00183104" />
              <joint name="wrist_2_joint" pos="0 0 0" axis="0 0 1" range="-6.28319 6.28319" actuatorfrcrange="-28 28" />
              <geom pos="0 0 -0.095" quat="1 0 0 0" type="mesh" rgba="0.7 0.7 0.7 1" mesh="wrist2" />
              <body name="wrist_3_link" pos="0 0.0823 -1.688e-11" quat="0.707107 -0.707107 0 0">
                <inertial pos="0 0 -0.001159" quat="0.5 0.5 -0.5 0.5" mass="0.1879" diaginertia="0.000132117 8.06248e-05 8.06248e-05" />
                <joint name="wrist_3_joint" pos="0 0 0" axis="0 0 1" range="-6.28319 6.28319" actuatorfrcrange="-28 28" />
                <geom pos="0 0 -0.0818" quat="0.707107 0.707107 0 0" type="mesh" rgba="0.7 0.7 0.7 1" mesh="wrist3" />
              </body>
            </body>
          </body>
        </body>
      </body>
    </body>
  </worldbody>
  <actuator>
    <general name="shoulder_pan_joint_actuator" joint="shoulder_pan_joint" gainprm="1" ctrlrange="-3.14 3.14" />
    <general name="shoulder_lift_joint_actuator" joint="shoulder_lift_joint" gainprm="1" ctrlrange="-3.14 3.14" />
    <general name="elbow_joint_actuator" joint="elbow_joint" gainprm="1" ctrlrange="-3.14 3.14" />
    <general name="wrist_1_joint_actuator" joint="wrist_1_joint" gainprm="1" ctrlrange="-3.14 3.14" />
    <general name="wrist_2_joint_actuator" joint="wrist_2_joint" gainprm="1" ctrlrange="-3.14 3.14" />
    <general name="wrist_3_joint_actuator" joint="wrist_3_joint" gainprm="1" ctrlrange="-3.14 3.14" />
  </actuator>
  <keyframe>
    <key name="home" qpos="0 0 0 0 0 0" />
  </keyframe>
</mujoco>
